<?xml version="1.0" encoding="UTF-8"?>
<!-- Generated by org.testng.reporters.JUnitReportReporter -->
<testsuite hostname="LAPTOP-KB4CSNC1" failures="0" tests="3" name="com.BusyQA.UITest.TestCases.Sprint1.TC_LoginTest" time="23.678" errors="1" timestamp="22 Feb 2021 14:59:29 GMT">
  <testcase classname="com.BusyQA.UITest.TestCases.Sprint1.TC_LoginTest" name="TC02_FailedLoginTest" time="0.527">
    <error message="Not matched expected [Invalid] but found [Invalid credentials]" type="java.lang.AssertionError">
      <![CDATA[java.lang.AssertionError: Not matched expected [Invalid] but found [Invalid credentials]
	at org.testng.Assert.fail(Assert.java:94)
	at org.testng.Assert.failNotEquals(Assert.java:494)
	at org.testng.Assert.assertEquals(Assert.java:123)
	at org.testng.Assert.assertEquals(Assert.java:176)
	at com.BusyQA.UITest.TestCases.Sprint1.TC_LoginTest.TC02_FailedLoginTest(TC_LoginTest.java:75)
	at java.base/jdk.internal.reflect.NativeMethodAccessorImpl.invoke0(Native Method)
	at java.base/jdk.internal.reflect.NativeMethodAccessorImpl.invoke(NativeMethodAccessorImpl.java:64)
	at java.base/jdk.internal.reflect.DelegatingMethodAccessorImpl.invoke(DelegatingMethodAccessorImpl.java:43)
	at java.base/java.lang.reflect.Method.invoke(Method.java:564)
	at org.testng.internal.MethodInvocationHelper.invokeMethod(MethodInvocationHelper.java:84)
	at org.testng.internal.Invoker.invokeMethod(Invoker.java:714)
	at org.testng.internal.Invoker.invokeTestMethod(Invoker.java:901)
	at org.testng.internal.Invoker.invokeTestMethods(Invoker.java:1231)
	at org.testng.internal.TestMethodWorker.invokeTestMethods(TestMethodWorker.java:127)
	at org.testng.internal.TestMethodWorker.run(TestMethodWorker.java:111)
	at org.testng.TestRunner.privateRun(TestRunner.java:767)
	at org.testng.TestRunner.run(TestRunner.java:617)
	at org.testng.SuiteRunner.runTest(SuiteRunner.java:348)
	at org.testng.SuiteRunner.access$000(SuiteRunner.java:38)
	at org.testng.SuiteRunner$SuiteWorker.run(SuiteRunner.java:382)
	at org.testng.internal.thread.ThreadUtil$2.call(ThreadUtil.java:64)
	at java.base/java.util.concurrent.FutureTask.run(FutureTask.java:264)
	at java.base/java.util.concurrent.ThreadPoolExecutor.runWorker(ThreadPoolExecutor.java:1130)
	at java.base/java.util.concurrent.ThreadPoolExecutor$Worker.run(ThreadPoolExecutor.java:630)
	at java.base/java.lang.Thread.run(Thread.java:832)
]]>
    </error>
  </testcase> <!-- TC02_FailedLoginTest -->
  <testcase classname="com.BusyQA.UITest.TestCases.Sprint1.TC_LoginTest" name="TC01_FailedLoginTest" time="19.812"/>
  <testcase classname="com.BusyQA.UITest.TestCases.Sprint1.TC_LoginTest" name="TC03_SuccessLoginTest" time="3.339"/>
</testsuite> <!-- com.BusyQA.UITest.TestCases.Sprint1.TC_LoginTest -->
